Workbook

Sheet Data_Unpaired
A1: Tài khoản | B1: Người tạo | C1: Nợ quy đổi | D1: Có quy đổi | E1: Số giao dịch | F1: Ngày giao dịch | G1: Nội dung | H1: Dòng gốc (Row) | I1: Người cập nhật
A2: 11310000000 | B2: QUYENNN.HCM.VTA | C2: 35826075 | D2: 0 | E2: R0526ĐTT0317 | F2: 46156 | G2: PCVT chuyển từ tk chuyên thu tiền điện sang tk thu chi SXK T03+04/2026 theo tờ trình số 28 TCKT ngày 12/05/2026 qua NH Đầu Tư | H2: 10646 | I2: QUYENNN.HCM.VTA
A3: 11310000000 | B3: THAOPTT.HCM.VTA | C3: 0 | D3: 200000000 | E3: T0526C021 | F3: 46164 | G3: Rút tiền về quỹ tiền mặt theo số sec DD 265235 ngày 22.05.2026 | H3: 10681 | I3: THAOPTT.HCM.VTA
A4: 14190000000 | B4: THAOPTT.HCM.VTA | C4: 0 | D4: 20415912 | E4: AP261312 | F4: 46170 | G4: Giải trừ tạm ứng cho bà Vũ Thanh Nguyên phục vụ công tác kiểm tra khối lượng các công trình ĐTXD năm 2025 | H4: 105 | I4: THAOPTT.HCM.VTA
A5: 14190000000 | B5: THAOPTT.HCM.VTA | C5: 0 | D5: 20919448 | E5: AP261313 | F5: 46170 | G5: Giải trừ tạm ứng cho ông Vũ Thanh Tâm P.QLĐT phục vụ công tác kiểm tra khối lượng các công trình ĐTXD năm 2025 | H5: 119 | I5: THAOPTT.HCM.VTA
A6: 14190000000 | B6: THAOPTT.HCM.VTA | C6: 20000000 | D6: 0 | E6: AP261313 | F6: 46170 | G6: Giải trừ tạm ứng cho ông Vũ Thanh Tâm P.QLĐT phục vụ công tác kiểm tra khối lượng các công trình ĐTXD năm 2025 | H6: 123 | I6: THAOPTT.HCM.VTA
A7: 14190000000 | B7: THAOPTT.HCM.VTA | C7: 20000000 | D7: 0 | E7: 421569 | F7: 46163 | G7: Chi tạm ứng cho bà Lê Thị Ngọc Châu phục vụ công tác SXKD T05-2026 | H7: 11354 | I7: THAOPTT.HCM.VTA
A8: 15110000000 | B8: OANHDTT.HCM.VTA | C8: 0 | D8: 1960000000 | E8: 01.VH2.10.0001 | F8: 46157 | G8: CT 25018 - Nhập theo PL HĐ 1481/HĐ-PCBRVT-AIT-VẠN XUÂN và hóa đơn số 21 ngày 28.04.2026 - Cty CP Đầu tư và Công Nghệ Vạn Xuân | H8: 1955 | I8: SYSADMIN
A9: 15190000000 | B9: SATTN.HCM.VTA | C9: 60761400 | D9: 0 | E9: 07.VH9.56.0048 | F9: 46167 | G9: 24027 Nhập điều chuyển vật tư thừa sau QT CT Chống quá tải TX Phú Mỹ 24027 | H9: 383 | I9: SYSADMIN
A10: 15190000000 | B10: SATTN.HCM.VTA | C10: 224208600 | D10: 0 | E10: 07.VH9.56.0048 | F10: 46167 | G10: 24027 Nhập điều chuyển vật tư thừa sau QT CT Chống quá tải TX Phú Mỹ 24027 | H10: 385 | I10: SYSADMIN
A11: 15190000000 | B11: SATTN.HCM.VTA | C11: 8149000 | D11: 0 | E11: 07.VH9.56.0049 | F11: 46168 | G11: 24027 Nhập điều chuyển từ kho VH9 ngoài về kho trong VH2 CT CQT TX Phú Mỹ 24027 | H11: 387 | I11: SYSADMIN
A12: 15190000000 | B12: SATTN.HCM.VTA | C12: 6216000 | D12: 0 | E12: 07.VH9.56.0046 | F12: 46167 | G12: 24025 Điều chuyển vật tư thừa sau quyết toán CT CQT 4 Huyện LĐ, ĐĐ, XM và Châu đức | H12: 390 | I12: SYSADMIN
A13: 15190000000 | B13: SATTN.HCM.VTA | C13: 17937600 | D13: 0 | E13: 07.VH9.56.0046 | F13: 46167 | G13: 24025 Điều chuyển vật tư thừa sau quyết toán CT CQT 4 Huyện LĐ, ĐĐ, XM và Châu đức | H13: 392 | I13: SYSADMIN
... A588: 33193000000 | B588: HA2TTT.HCM.VTA | C588: 0 | D588: 24000 | E588: 01.VH8.12.0053 | F588: 46154 | G588: 23006-Nhập Vtư theo BBĐG chất lượng VTTB thu hồi của Ctr DD Ẹo Ông Từ đến Cầu Cỏ May | H588: 3043 | I588: SYSADMIN
A589: 33193000000 | B589: QUYENNN.HCM.VTA | C589: 0 | D589: 1567417064 | E589: G0526ĐTT0760 | F589: 46147 | H589: 10584 | I589: QUYENNN.HCM.VTA
A590: 33193000000 | B590: QUYENNN.HCM.VTA | C590: 0 | D590: 596605 | E590: G0526ĐTT0784 | F590: 46155 | H590: 10612 | I590: QUYENNN.HCM.VTA
A591: 33193000000 | B591: QUYENNN.HCM.VTA | C591: 0 | D591: 460000 | E591: G0526ĐTT0787 | F591: 46156 | H591: 10629 | I591: QUYENNN.HCM.VTA
A592: 33193000000 | B592: QUYENNN.HCM.VTA | C592: 0 | D592: 282991644 | E592: G0526ĐTT0800 | F592: 46161 | H592: 10643 | I592: QUYENNN.HCM.VTA
A593: 33193000000 | B593: QUYENNN.HCM.VTA | C593: 0 | D593: 77012175 | E593: G0526ĐTT0768 | F593: 46149 | H593: 10664 | I593: QUYENNN.HCM.VTA
A594: 33193000000 | B594: QUYENNN.HCM.VTA | C594: 0 | D594: 18399785 | E594: G0526ĐTT0797 | F594: 46160 | H594: 10667 | I594: QUYENNN.HCM.VTA
A595: 33193000000 | B595: QUYENNN.HCM.VTA | C595: 0 | D595: 82637285 | E595: G0526ĐTT0781 | F595: 46154 | H595: 10723 | I595: QUYENNN.HCM.VTA
A596: 33193000000 | B596: QUYENNN.HCM.VTA | C596: 0 | D596: 72761921 | E596: G0526ĐTT0789 | F596: 46157 | H596: 10749 | I596: QUYENNN.HCM.VTA
A597: 33193000000 | B597: QUYENNN.HCM.VTA | C597: 0 | D597: 620579 | E597: G0526ĐTT0792 | F597: 46158 | H597: 10765 | I597: QUYENNN.HCM.VTA
A598: 33193000000 | B598: QUYENNN.HCM.VTA | C598: 0 | D598: 1403027 | E598: G0526ĐTT0811 | F598: 46164 | H598: 10777 | I598: QUYENNN.HCM.VTA
A599: 33193000000 | B599: QUYENNN.HCM.VTA | C599: 0 | D599: 476582 | E599: G0526ĐTT0753 | F599: 46145 | H599: 10789 | I599: QUYENNN.HCM.VTA
A600: 33193000000 | B600: QUYENNN.HCM.VTA | C600: 0 | D600: 40209999 | E600: G0526ĐTT0756 | F600: 46146 | H600: 10798 | I600: QUYENNN.HCM.VTA
A601: 33193000000 | B601: THAOPTT.HCM.VTA | C601: 0 | D601: 237865 | E601: T0526C020 | F601: 46157 | G601: Nhập tiền khách hàng Phạm Văn Giới - MKH PB15010021934 tự ý tăng công suất Điện MTMN | H601: 10824 | I601: THAOPTT.HCM.VTA
A602: 33193000000 | B602: QUYENNN.HCM.VTA | C602: 0 | D602: 809768713 | E602: G0526ĐTT0777 | F602: 46153 | H602: 10851 | I602: QUYENNN.HCM.VTA
A603: 33193000000 | B603: QUYENNN.HCM.VTA | C603: 0 | D603: 61104244 | E603: G0526ĐTT00771 | F603: 46150 | H603: 10865 | I603: QUYENNN.HCM.VTA
A604: 33193000000 | B604: QUYENNN.HCM.VTA | C604: 0 | D604: 176984203 | E604: G0526ĐTT0763 | F604: 46148 | H604: 10868 | I604: QUYENNN.HCM.VTA
A605: 33193000000 | B605: QUYENNN.HCM.VTA | C605: 0 | D605: 1739664 | E605: G0526ĐTT0774 | F605: 46151 | H605: 10884 | I605: QUYENNN.HCM.VTA
A606: 33193000000 | B606: QUYENNN.HCM.VTA | C606: 0 | D606: 365420 | E606: G0526ĐTT0816 | F606: 46167 | H606: 11048 | I606: QUYENNN.HCM.VTA
A607: 33193000000 | B607: QUYENNN.HCM.VTA | C607: 0 | D607: 71467948 | E607: G0526ĐTT0808 | F607: 46163 | H607: 11071 | I607: QUYENNN.HCM.VTA
A608: 33193000000 | B608: QUYENNN.HCM.VTA | C608: 0 | D608: 201569864 | E608: G0526ĐTT0803 | F608: 46162 | H608: 11096 | I608: QUYENNN.HCM.VTA
A609: 33193000000 | B609: QUYENNN.HCM.VTA | C609: 0 | D609: 255479000 | E609: G0526ĐTT0819 | F609: 46168 | H609: 11103 | I609: QUYENNN.HCM.VTA
A610: 33193000000 | B610: CHAULTN.HCM.VTA | C610: 0 | D610: 1792931000 | E610: 1605 | F610: 46160 | G610: 1388ĐĐ - Điều động VTTB cho PC Bến cát theo TB 2205 ngày 06/05/2026 - HĐ 40/18.05.2026 | H610: 11244 | I610: CHAULTN.HCM.VTA
A611: 33193000000 | B611: CHAULTN.HCM.VTA | C611: 0 | D611: 2631095000 | E611: 1606 | F611: 46161 | G611: 1388ĐĐ - Điều động VTTB cho PC Thuận An theo TB 2188 ngày 05/05/2026 - HĐ 41/19.05.2026 | H611: 11257 | I611: CHAULTN.HCM.VTA
A612: 33194000000 | B612: THAOPTT.HCM.VTA | C612: 95926 | D612: 0 | E612: AP261310 | F612: 46170 | G612: Giải trừ tạm ứng cho bà Phạm Thị Thu Thảo-VP tạm ứng phục vụ công tác teabreak tháng 05-2026 | H612: 337 | I612: THAOPTT.HCM.VTA
A613: 33194000000 | B613: QUYENNN.HCM.VTA | C613: 70000 | D613: 0 | E613: R0526ĐTT0293 | F613: 46147 | G613: Chuyển trả phí chuyển tiền T05/2026 BIDV | H613: 10597 | I613: QUYENNN.HCM.VTA
A614: 33194000000 | B614: QUYENNN.HCM.VTA | C614: 70000 | D614: 0 | E614: R0526ĐTT0336 | F614: 46164 | G614: Chuyển trả phí chuyển tiền T05/2026 BIDV | H614: 10606 | I614: QUYENNN.HCM.VTA
...

Sheet DoiChieu_TKTG
B2: ĐỐI CHIẾU SỐ LIỆU TÀI KHOẢN TRUNG GIAN - ERP
B3: Phân tích tự động số lệch chênh lệch Nợ/Có và truy tìm Người tạo phát sinh lệch
B5: Chọn tài khoản đối chiếu: | C5: 33191000000
B7: BẢNG TỔNG HỢP PHÁT SINH LỆCH | H7: BẢNG TRA CỨU NGƯỜI LÀM LỆCH (ĐỘNG THEO Ô CHỌN C5)
B8: Tài khoản | C8: Tổng Phát sinh Nợ | D8: Tổng Phát sinh Có | E8: Chênh lệch (Nợ-Có) | F8: Trạng thái | H8: Người tạo (Creator) | I8: Tổng Phát sinh Nợ | J8: Tổng Phát sinh Có | K8: Chênh lệch (Nợ-Có) | L8: Trạng thái
B9: 11310000000 | C9: 7762679244 | D9: 7926853169 | E9: =C9-D9 | F9: =IF(ROUND(E9,2)=0, "Khớp", "Lệch số") | H9: CHAULTN.HCM.VTA | I9: =SUMIFS(Data_Unpaired!C:C, Data_Unpaired!A:A, $C$5, Data_Unpaired!B:B, H9) | J9: =SUMIFS(Data_Unpaired!D:D, Data_Unpaired!A:A, $C$5, Data_Unpaired!B:B, H9) | K9: =I9-J9 | L9: =IF(AND(I9=0,J9=0), "", IF(ROUND(K9,2)=0, "Khớp", "Lệch số"))
B10: 14190000000 | C10: 245000000 | D10: 249650920 | E10: =C10-D10 | F10: =IF(ROUND(E10,2)=0, "Khớp", "Lệch số") | H10: DIEULX.HCM.VTA | I10: =SUMIFS(Data_Unpaired!C:C, Data_Unpaired!A:A, $C$5, Data_Unpaired!B:B, H10) | J10: =SUMIFS(Data_Unpaired!D:D, Data_Unpaired!A:A, $C$5, Data_Unpaired!B:B, H10) | K10: =I10-J10 | L10: =IF(AND(I10=0,J10=0), "", IF(ROUND(K10,2)=0, "Khớp", "Lệch số"))
B11: 15110000000 | C11: 1960000000 | D11: 1960000000 | E11: =C11-D11 | F11: =IF(ROUND(E11,2)=0, "Khớp", "Lệch số") | H11: HA2TTT.HCM.VTA | I11: =SUMIFS(Data_Unpaired!C:C, Data_Unpaired!A:A, $C$5, Data_Unpaired!B:B, H11) | J11: =SUMIFS(Data_Unpaired!D:D, Data_Unpaired!A:A, $C$5, Data_Unpaired!B:B, H11) | K11: =I11-J11 | L11: =IF(AND(I11=0,J11=0), "", IF(ROUND(K11,2)=0, "Khớp", "Lệch số"))
B12: 15190000000 | C12: 8009349173 | D12: 8009349173 | E12: =C12-D12 | F12: =IF(ROUND(E12,2)=0, "Khớp", "Lệch số") | H12: HUENT.HCM.VTA | I12: =SUMIFS(Data_Unpaired!C:C, Data_Unpaired!A:A, $C$5, Data_Unpaired!B:B, H12) | J12: =SUMIFS(Data_Unpaired!D:D, Data_Unpaired!A:A, $C$5, Data_Unpaired!B:B, H12) | K12: =I12-J12 | L12: =IF(AND(I12=0,J12=0), "", IF(ROUND(K12,2)=0, "Khớp", "Lệch số"))
B13: 24190000000 | C13: 0 | D13: 0 | E13: =C13-D13 | F13: =IF(ROUND(E13,2)=0, "Khớp", "Lệch số") | H13: HUONGDTT.HCM.VTA | I13: =SUMIFS(Data_Unpaired!C:C, Data_Unpaired!A:A, $C$5, Data_Unpaired!B:B, H13) | J13: =SUMIFS(Data_Unpaired!D:D, Data_Unpaired!A:A, $C$5, Data_Unpaired!B:B, H13) | K13: =I13-J13 | L13: =IF(AND(I13=0,J13=0), "", IF(ROUND(K13,2)=0, "Khớp", "Lệch số"))
B14: 33191000000 | C14: 0 | D14: 2112575000 | E14: =C14-D14 | F14: =IF(ROUND(E14,2)=0, "Khớp", "Lệch số") | H14: KHANH2LQ.HCM.VTA | I14: =SUMIFS(Data_Unpaired!C:C, Data_Unpaired!A:A, $C$5, Data_Unpaired!B:B, H14) | J14: =SUMIFS(Data_Unpaired!D:D, Data_Unpaired!A:A, $C$5, Data_Unpaired!B:B, H14) | K14: =I14-J14 | L14: =IF(AND(I14=0,J14=0), "", IF(ROUND(K14,2)=0, "Khớp", "Lệch số"))
B15: 33192000000 | C15: 0 | D15: 1652341116 | E15: =C15-D15 | F15: =IF(ROUND(E15,2)=0, "Khớp", "Lệch số") | H15: OANHDTT.HCM.VTA | I15: =SUMIFS(Data_Unpaired!C:C, Data_Unpaired!A:A, $C$5, Data_Unpaired!B:B, H15) | J15: =SUMIFS(Data_Unpaired!D:D, Data_Unpaired!A:A, $C$5, Data_Unpaired!B:B, H15) | K15: =I15-J15 | L15: =IF(AND(I15=0,J15=0), "", IF(ROUND(K15,2)=0, "Khớp", "Lệch số"))
B16: 33193000000 | C16: 9010382245 | D16: 13888403439 | E16: =C16-D16 | F16: =IF(ROUND(E16,2)=0, "Khớp", "Lệch số") | H16: QUYENNN.HCM.VTA | I16: =SUMIFS(Data_Unpaired!C:C, Data_Unpaired!A:A, $C$5, Data_Unpaired!B:B, H16) | J16: =SUMIFS(Data_Unpaired!D:D, Data_Unpaired!A:A, $C$5, Data_Unpaired!B:B, H16) | K16: =I16-J16 | L16: =IF(AND(I16=0,J16=0), "", IF(ROUND(K16,2)=0, "Khớp", "Lệch số"))
B17: 33194000000 | C17: 5996840 | D17: 0 | E17: =C17-D17 | F17: =IF(ROUND(E17,2)=0, "Khớp", "Lệch số") | H17: SATTN.HCM.VTA | I17: =SUMIFS(Data_Unpaired!C:C, Data_Unpaired!A:A, $C$5, Data_Unpaired!B:B, H17) | J17: =SUMIFS(Data_Unpaired!D:D, Data_Unpaired!A:A, $C$5, Data_Unpaired!B:B, H17) | K17: =I17-J17 | L17: =IF(AND(I17=0,J17=0), "", IF(ROUND(K17,2)=0, "Khớp", "Lệch số"))
B18: 33195000000 | C18: 0 | D18: 0 | E18: =C18-D18 | F18: =IF(ROUND(E18,2)=0, "Khớp", "Lệch số") | H18: THAOPTT.HCM.VTA | I18: =SUMIFS(Data_Unpaired!C:C, Data_Unpaired!A:A, $C$5, Data_Unpaired!B:B, H18) | J18: =SUMIFS(Data_Unpaired!D:D, Data_Unpaired!A:A, $C$5, Data_Unpaired!B:B, H18) | K18: =I18-J18 | L18: =IF(AND(I18=0,J18=0), "", IF(ROUND(K18,2)=0, "Khớp", "Lệch số"))
B19: 33196100000 | C19: 64471587 | D19: 2694491590 | E19: =C19-D19 | F19: =IF(ROUND(E19,2)=0, "Khớp", "Lệch số") | H19: THUTT.HCM.VTA | I19: =SUMIFS(Data_Unpaired!C:C, Data_Unpaired!A:A, $C$5, Data_Unpaired!B:B, H19) | J19: =SUMIFS(Data_Unpaired!D:D, Data_Unpaired!A:A, $C$5, Data_Unpaired!B:B, H19) | K19: =I19-J19 | L19: =IF(AND(I19=0,J19=0), "", IF(ROUND(K19,2)=0, "Khớp", "Lệch số"))
B20: 33198000000 | C20: 608719822 | D20: 357390446 | E20: =C20-D20 | F20: =IF(ROUND(E20,2)=0, "Khớp", "Lệch số") | H20: TUAN2HM.HCM.VTA | I20: =SUMIFS(Data_Unpaired!C:C, Data_Unpaired!A:A, $C$5, Data_Unpaired!B:B, H20) | J20: =SUMIFS(Data_Unpaired!D:D, Data_Unpaired!A:A, $C$5, Data_Unpaired!B:B, H20) | K20: =I20-J20 | L20: =IF(AND(I20=0,J20=0), "", IF(ROUND(K20,2)=0, "Khớp", "Lệch số"))
B21: Tổng cộng | C21: =SUM(C9:C20) | D21: =SUM(D9:D20) | E21: =C21-D21 | F21: =IF(ROUND(E21,2)=0, "Khớp", "Lệch") | H21: Tổng cộng | I21: =SUM(I9:I20) | J21: =SUM(J9:J20) | K21: =I21-J21 | L21: =IF(ROUND(K21,2)=0, "Khớp", "Lệch")
B22: Hướng dẫn sử dụng:
B23: 1. Click chọn ô C5, bấm vào dấu mũi tên dropdown hiện lên và chọn tài khoản cần kiểm tra.
B24: 2. Bảng đối chiếu người tạo bên phải (Cột H -> L) sẽ tự động nhảy số tiền tương ứng tài khoản chọn.
B25: 3. Xem bảng chi tiết ở sheet 'ChiTiet_GiaoDich_Lech' để tìm chính xác dòng bị lỗi để điều chỉnh.

Sheet ChiTiet_GiaoDich_Lech
B2: CHI TIẾT CÁC GIAO DỊCH CHƯA ĐỐI ỨNG (GÂY LỆCH SỐ THỰC TẾ)
B3: Báo cáo liệt kê các giao dịch đơn lẻ bị lệch ròng, loại bỏ tất cả các giao dịch đã đối ứng tự động
B6: TÀI KHOẢN: 11310000000 - Danh sách giao dịch làm lệch số thực tế
B7: Dòng gốc (Row) | C7: Số chứng từ | D7: Ngày giao dịch | E7: Số tiền Nợ | F7: Số tiền Có | G7: Người tạo (Creator) | H7: Người cập nhật | I7: Nội dung giao dịch
B8: 10646 | C8: R0526ĐTT0317 | D8: 46156 | E8: 35826075 | F8: 0 | G8: QUYENNN.HCM.VTA | H8: QUYENNN.HCM.VTA | I8: PCVT chuyển từ tk chuyên thu tiền điện sang tk thu chi SXK T03+04/2026 theo tờ trình số 28 TCKT ngày 12/05/2026 qua NH Đầu Tư
B9: 10681 | C9: T0526C021 | D9: 46164 | E9: 0 | F9: 200000000 | G9: THAOPTT.HCM.VTA | H9: THAOPTT.HCM.VTA | I9: Rút tiền về quỹ tiền mặt theo số sec DD 265235 ngày 22.05.2026
B10: Tổng cộng chưa khớp | E10: =SUM(E8:E9) | F10: =SUM(F8:F9) | G10: Chênh lệch (Nợ-Có): | H10: =E10-F10
B13: TÀI KHOẢN: 14190000000 - Danh sách giao dịch làm lệch số thực tế
B14: Dòng gốc (Row) | C14: Số chứng từ | D14: Ngày giao dịch | E14: Số tiền Nợ | F14: Số tiền Có | G14: Người tạo (Creator) | H14: Người cập nhật | I14: Nội dung giao dịch
B15: 105 | C15: AP261312 | D15: 46170 | E15: 0 | F15: 20415912 | G15: THAOPTT.HCM.VTA | H15: THAOPTT.HCM.VTA | I15: Giải trừ tạm ứng cho bà Vũ Thanh Nguyên phục vụ công tác kiểm tra khối lượng các công trình ĐTXD năm 2025
B16: 119 | C16: AP261313 | D16: 46170 | E16: 0 | F16: 20919448 | G16: THAOPTT.HCM.VTA | H16: THAOPTT.HCM.VTA | I16: Giải trừ tạm ứng cho ông Vũ Thanh Tâm P.QLĐT phục vụ công tác kiểm tra khối lượng các công trình ĐTXD năm 2025
B17: 123 | C17: AP261313 | D17: 46170 | E17: 20000000 | F17: 0 | G17: THAOPTT.HCM.VTA | H17: THAOPTT.HCM.VTA | I17: Giải trừ tạm ứng cho ông Vũ Thanh Tâm P.QLĐT phục vụ công tác kiểm tra khối lượng các công trình ĐTXD năm 2025
B18: 11354 | C18: 421569 | D18: 46163 | E18: 20000000 | F18: 0 | G18: THAOPTT.HCM.VTA | H18: THAOPTT.HCM.VTA | I18: Chi tạm ứng cho bà Lê Thị Ngọc Châu phục vụ công tác SXKD T05-2026
B19: Tổng cộng chưa khớp | E19: =SUM(E15:E18) | F19: =SUM(F15:F18) | G19: Chênh lệch (Nợ-Có): | H19: =E19-F19
B22: TÀI KHOẢN: 15110000000 - Danh sách giao dịch làm lệch số thực tế
B23: Dòng gốc (Row) | C23: Số chứng từ | D23: Ngày giao dịch | E23: Số tiền Nợ | F23: Số tiền Có | G23: Người tạo (Creator) | H23: Người cập nhật | I23: Nội dung giao dịch
B24: 1955 | C24: 01.VH2.10.0001 | D24: 46157 | E24: 0 | F24: 1960000000 | G24: OANHDTT.HCM.VTA | H24: SYSADMIN | I24: CT 25018 - Nhập theo PL HĐ 1481/HĐ-PCBRVT-AIT-VẠN XUÂN và hóa đơn số 21 ngày 28.04.2026 - Cty CP Đầu tư và Công Nghệ Vạn Xuân
B25: Tổng cộng chưa khớp | E25: =SUM(E24:E24) | F25: =SUM(F24:F24) | G25: Chênh lệch (Nợ-Có): | H25: =E25-F25
B28: TÀI KHOẢN: 33191000000 - Danh sách giao dịch làm lệch số thực tế
B29: Dòng gốc (Row) | C29: Số chứng từ | D29: Ngày giao dịch | E29: Số tiền Nợ | F29: Số tiền Có | G29: Người tạo (Creator) | H29: Người cập nhật | I29: Nội dung giao dịch
B30: 1067 | C30: 01.VH1.10.0041 | D30: 46164 | E30: 0 | F30: 5833333 | G30: SATTN.HCM.VTA | H30: SYSADMIN | I30: Nhập theo hoá đơn số 561 của công ty Deep flowx
B31: 1069 | C31: 01.VH1.10.0044 | D31: 46165 | E31: 0 | F31: 3400000 | G31: SATTN.HCM.VTA | H31: SYSADMIN | I31: Nhập theo hoá đơn số 96 của CH Nguyễn Văn Tạo
B32: 1247 | C32: 01.VH1.10.0038 | D32: 46157 | E32: 0 | F32: 27361111 | G32: SATTN.HCM.VTA | H32: SYSADMIN | I32: Nhập theo hoá đơn số 221 của Công ty TNHH Tiến thành Water
B33: 1554 | C33: 01.VH1.10.0045 | D33: 46169 | E33: 0 | F33: 26150000 | G33: KHANH2LQ.HCM.VTA | H33: SYSADMIN | I33: Nhập máy tính xách tay Dell 14 DC14250, Core 7 - 150U theo HĐơn 00000360 ngày 27/05/26 - CTy NLT
B34: 1650 | C34: 01.VH1.10.0039 | D34: 46161 | E34: 0 | F34: 23500000 | G34: KHANH2LQ.HCM.VTA | H34: SYSADMIN | I34: Nhập máy tính để bàn HP Pro Tower 280 G9 PCI (bao gồm màn hình Dell) theo Hđơn 00000080 ngày 14/5/26 - Cty Khách Đế
B35: 2244 | C35: 01.VH1.10.0040 | D35: 46163 | E35: 0 | F35: 9180000 | G35: SATTN.HCM.VTA | H35: SYSADMIN | I35: Nhập theo hoá đơn số 00012 Công ty Thanh Bình Electric
B36: 2246 | C36: 01.VH1.10.0040 | D36: 46163 | E36: 0 | F36: 4340000 | G36: SATTN.HCM.VTA | H36: SYSADMIN | I36: Nhập theo hoá đơn số 00012 Công ty Thanh Bình Electric
B37: 2663 | C37: 01.VH1.10.0042 | D37: 46165 | E37: 0 | F37: 9055556 | G37: SATTN.HCM.VTA | H37: SYSADMIN | I37: Nhập theo hoá đơn số 279 của Công ty Kim Minh
B38: 2816 | C38: 01.VH1.10.0043 | D38: 46165 | E38: 0 | F38: 8750000 | G38: SATTN.HCM.VTA | H38: SYSADMIN | I38: Nhập theo hoá đơn số 49 của HKD Nguyễn Văn Bình
B39: 2818 | C39: 01.VH1.10.0043 | D39: 46165 | E39: 0 | F39: 2500000 | G39: SATTN.HCM.VTA | H39: SYSADMIN | I39: Nhập theo hoá đơn số 49 của HKD Nguyễn Văn Bình
B40: 3114 | C40: 01.VH1.10.0040 | D40: 46163 | E40: 0 | F40: 4350000 | G40: SATTN.HCM.VTA | H40: SYSADMIN | I40: Nhập theo hoá đơn số 00012 Công ty Thanh Bình Electric
B41: 3116 | C41: 01.VH1.10.0040 | D41: 46163 | E41: 0 | F41: 11550000 | G41: SATTN.HCM.VTA | H41: SYSADMIN | I41: Nhập theo hoá đơn số 00012 Công ty Thanh Bình Electric
B42: 3118 | C42: 01.VH1.10.0040 | D42: 46163 | E42: 0 | F42: 16605000 | G42: SATTN.HCM.VTA | H42: SYSADMIN | I42: Nhập theo hoá đơn số 00012 Công ty Thanh Bình Electric
B43: Tổng cộng chưa khớp | E43: =SUM(E30:E42) | F43: =SUM(F30:F42) | G43: Chênh lệch (Nợ-Có): | H43: =E43-F43
B46: TÀI KHOẢN: 33192000000 - Danh sách giao dịch làm lệch số thực tế
B47: Dòng gốc (Row) | C47: Số chứng từ | D47: Ngày giao dịch | E47: Số tiền Nợ | F47: Số tiền Có | G47: Người tạo (Creator) | H47: Người cập nhật | I47: Nội dung giao dịch
B48: 11 | C48: AP261309 | D48: 46169 | E48: 0 | F48: 660853804 | G48: TUAN2HM.HCM.VTA | H48: TUAN2HM.HCM.VTA | I48: VTAD2605001_Tạm ứng 20% SCL lưới Trung hạ thế và TBA 2026
B49: 13 | C49: AP261311 | D49: 46169 | E49: 0 | F49: 991487312 | G49: TUAN2HM.HCM.VTA | H49: TUAN2HM.HCM.VTA | I49: VTAD2605001_tạm ứng 20% SCL lưới THT & TBA 2026_Cty lạc Thành
B50: Tổng cộng chưa khớp | E50: =SUM(E48:E49) | F50: =SUM(F48:F49) | G50: Chênh lệch (Nợ-Có): | H50: =E50-F50
B53: TÀI KHOẢN: 33193000000 - Danh sách giao dịch làm lệch số thực tế
...
